Workbook

Sheet Легенда
A1: № плц | B1: выработанные рецепты в указанную дату
A2: наимен рецепта
A3: дата
A5: № плц | B5: поставленные на выработку рецепты
A6: наимен рецепта
A7: дата
A9: № плц | B9: планируемые на выработку рецепты
A10: наимен рецепта
A11: дата
A13: число | B13: планировать закупку
A14: число | B14: перевезти с Липковской или закупить
A15: отр. число | B15: СРОЧНО ЗАКУПАТЬ!!!!

Sheet 1_квартал
GQ1: число | GR1: планировать закупку, держать на контроле | GU1: п. - партия
A2: число | B2: остатки, которые надо закрыть | GQ2: число | GR2: перевезти с Липковской или закупить
A3: число | B3: на пересчет рецепта | GQ3: отр. число | GR3: СРОЧНО ЗАКУПАТЬ!!!!
J4: ФАКТ | FW4: ПЛАН | GI4: КАЗАХСТАН
A5: № п/п | B5: сырье | C5: Полоцк КХП | G5: СРЕДНЕМЕСЯЧНЫЙ РАСХОД за текущий квартал | J5: январь | K5: 2 | L5: 3 | M5: 7 | N5: 9 | O5: 10 | P5: 11 | Q5: 12 | R5: 14 | S5: 13 | T5: 16 | U5: 17 | V5: 14 | W5: 21 | X5: 15 | Y5: 28 | Z5: 15 | AA5: 25 | AB5: 24 | AC5: 26 | AD5: 40 | AE5: 44 | AF5: 45 | AG5: 46 | AH5: 37 | AI5: 30 | AJ5: 50 | AK5: 12 | AL5: 43 | AM5: 15 | AN5: 38 | AO5: 11 | AP5: 29 | AQ5: 42 | AR5: 60 | AS5: 61 | AT5: 62 | AU5: 33 | AV5: 53 | AW5: 3 | AX5: 48 | AY5: 35 | AZ5: 36 | BA5: 34 | BB5: 32 | BC5: 51 А | BD5: 52 | BE5: 10 | BF5: 27 | BG5: 71 | BH5: 16 | BI5: 25 | BJ5: Расход за мес. (оперативный) | BK5: февраль | BL5: 74 | BM5: 13 | BN5: 68 | BO5: 70 | BP5: 73 | BQ5: 67 | BR5: 85 | BS5: 24 | BT5: 89 | BU5: 93 | BV5: 94 | BW5: 95 | BX5: 24 | BY5: 92 | BZ5: 97 | CA5: 91 | CB5: 75 | CC5: 101 | CD5: 91 | CE5: 103 | CF5: 90 | CG5: 106 | CH5: 107 | CI5: 108 | CJ5: 113 | CK5: 42 | CL5: 115 | CM5: 117 | CN5: 76 | CO5: 123 | CP5: 68 | CQ5: 124 | CR5: 116 | CS5: 41 | CT5: 112 | CU5: 110 | CV5: 111 | CW5: 49 | CX5: 126 | CY5: 98 | CZ5: 42 | DA5: 130 | DB5: 50 | DC5: 129 | DD5: 128 | DE5: 127 | DF5: 114 | DG5: 135 | DH5: 136 | DI5: 134 | DJ5: 139 | DK5: 46 | DL5: 142 | DM5: 141 | DN5: 135 | DO5: 136 | DP5: 134 | DQ5: 55 | DR5: 137 | DS5: Расход за текущий мес. (оперативный) | DT5: март | DU5: 144 | DV5: 150 | DW5: 151 | DX5: 42 | DY5: 145 | DZ5: 156 | EA5: 162 | EB5: 161 | EC5: 163 | ED5: 164 | EE5: 165 | EF5: 166 | EG5: 168 | EH5: 169 | EI5: 135 | EJ5: 136 | EK5: 158 | EL5: 171 | EM5: 20 | EN5: 134 | EO5: 135 | EP5: 136 | EQ5: 167 | ER5: 23 | ES5: 136 | ET5: 172 | EU5: 173 | EV5: 179 | EW5: 50 | EX5: 129 | EY5: 130 | EZ5: 182 | FA5: 68 | FB5: 185 | FC5: 183 | FD5: 178 | FE5: 42 | FF5: 191 | FG5: 184 | FH5: 198 | FI5: 191 | FJ5: 161 | FK5: 199 | FL5: 135 | FM5: 160 | FN5: 190 | FO5: 204 | FP5: 193 | FQ5: 193 | FR5: 194 | FS5: 208 | FT5: 168 | FU5: Расход за текущий мес. (оперативный) | GP5: ИТОГО | GQ5: Остаток на Полоцке после произв-ва | GR5: Запас на ОТЧЕТНУЮ дату | GS5: =G5 -> СРЕДНЕМЕСЯЧНЫЙ РАСХОД за текущий квартал | GT5: РАСХОД ЗА предыдущий месяц | GV5: годность | GW5: запас в месяцах
C6: декабрь | D6: январь | E6: февраль | F6: март | H6: Остаток на начало месяца | I6: Остаток ЗА ОТЧЕТНУЮ дату | K6: ДП60-3, дойное, Бакуново | L6: ДП60-3, дойное, АгроСолы | M6: ДП60-3 дойное, Савушкина пуща | N6: ДП60-3 дойное Мумуша, Агро-Детковичи, БИРЖА | O6: ДП60-3 1й сух, Свитязянка | P6: ДП60-3 2й сух, Свитязянка | Q6: ДП60-3 НОВОТЕЛ, Свитязянка | R6: ДП60-3 2й сух, Савушкина пуща, Савушкино | S6: ДП60-3 дойное Мумуша (ДейриБаланс), Макарово-агро, БИРЖА | T6: ДП60-3 1й сух, Савушкино | U6: ДП60-3 НОВОТЕЛ, Городилово | V6: ДП60-3 2й сух, Савушкино | W6: ДП60-3 дойное, Киселёвцы | X6: ДП60-3 НОВОТЕЛ, Савушкино | Y6: ДП60-3, дойное, Осовецкий | Z6: ДП60-3 НОВОТЕЛ, Савушкина пуща | AA6: ДП60-3 2й сух, Савушкина пуща | AB6: ДП60-3 НОВОТЕЛ, Савушкина пуща | AC6: ДП60-3 дойное, Савушкина пуща | AD6: ДП60-3 мастит, Видомлянское | AE6: ДП60-3 1й сух, Зеленевичи | AF6: ДП60-3 2й сух, Зеленевичи | AG6: ДП60-3 НОВОТЕЛ, Зеленевичи | AH6: ДП60-3 НОВОТЕЛ, Восх.заря | AI6: ДП60-3 дойное, Восх.заря | AJ6: ДП60-3 дойное Мумуша, Зеленевичи | AK6: ДПКР-2, Калф, Восх.заря | AL6: ДП60-3 НОВОТЕЛ, ФХ Юлиан | AM6: ДПКР-2 Хайфер, ФХ Юлиан | AN6: ДП60-3 2й сух, Восх.заря | AO6: ДПКР-2 Хайфер, Восх.заря | AP6: ДП60-3 1й сух, Восх. Заря | AQ6: ДП60-3 2й сух, ФХ Юлиан | AR6: ДП60-3 2й сух, Осовецкий | AS6: ДП60-3 НОВОТЕЛ, Осовецкий | AT6: ДП60-3 1й сух, Осовецкий | AU6: ДП60-3 2й сух, Бакуново | AV6: ДП60-3 1й сух, Шапчицы | AW6: ДП60-3, дойное, АгроСолы | AX6: ДП60-3 дойное Мумуша, с-з Минский | AY6: ДП60-3 1й сух, АгроМилк, БИРЖА | AZ6: ДП60-3 2й сух, АгроМилк, БИРЖА | BA6: ДП60-3 НОВОТЕЛ, АгроМилк, БИРЖА | BB6: ДП60-3 НОВОТЕЛ, Бакуново | BC6: ДП60-3 дойное 1 Мая | BD6: ДП60-3 1й сух 1 Мая | BE6: ДПКР-1 Мумуша в к/к Восх.заря, ФХ Юлиан | BF6: ДПКР-2, в к/к | BG6: ДП60-3 дойное, Савушкина пуща | BH6: ДП60-3 1й сух, Утес | BI6: ДП60-3 2й сух, Утес | BL6: ДП60-3 дойное, Полесская нива | BM6: ДП60-3 дойное Мумуша (ДейриБаланс), Макарово-агро, БИРЖА | BN6: ДП60-3 1й сух, ФХ Юлиан | BO6: ДП60-3 дойное, ФХ Юлиан | BP6: ДП60-3 1й сух, Полесская нива | BQ6: ДП60-3 дойное Мумуша, Лебедева Ветка | BR6: ДП60-3 2й сух, Журавлиное, БИРЖА | BS6: ДП60-3 НОВОТЕЛ, Савушкино | BT6: ДП60-3 дойное, Агросолы | BU6: ДП60-3 дойное, Киселевцы | BV6: ДП60-3 2й сух, Киселевцы | BW6: ДП60-3 2й сух Мумуша, Припять-2009, БИРЖА | BX6: ДП60-3 НОВОТЕЛ, Савушкино | BY6: ДП60-3 НОВОТЕЛ, Городилово | BZ6: ДП60-3 1й сух, Савушкино | CA6: ДП60-3 2й сух, Савушкино | CB6: ДП60-3 дойное, Бакуново | CC6: ДП60-3 дойное Мумуша, Минский | CD6: ДП60-3 2й сух, Савушкина пуща | CE6: ДП60-3 1й сух, Шапчицы | CF6: ДП60-3 НОВОТЕЛ, Савушкина пуща | CG6: ДП60-3 1й сух, Свитязянка | CH6: ДП60-3 2й сух, Свитязянка | CI6: ДП60-3 НОВОТЕЛ, Свитязянка | CJ6: ДП60-3 дойное, Осовецкий | CK6: ДПКР-2 Хайфер, ФХ Юлиан | CL6: ДП60-3 2й сух, ФХ Юлиан | CM6: ДП60-3 НОВОТЕЛ, ФХ Юлиан | CN6: ДП60-3 дойное Мумуша, Агро-Детковичи, БИРЖА | CO6: ДП60-3 НОВОТЕЛ, Городилово | CP6: ДП60-3 1й сух, ФХ Юлиан | CQ6: ДП60-3 дойное, Агросолы | CR6: ДП60-3 1й сух, Минский | CS6: ДПКР-2, КАЗАХСТАН | CT6: ДП60-3 дойное, КАЗАХСТАН | CU6: ДП60-3 1й сух, КАЗАХСТАН | CV6: ДП60-3 2й сух, КАЗАХСТАН | CW6: ПКР-2, Газовик-Сипаково, БИРЖА | CX6: ДП60-3 дойное, Савушкина пуща | CY6: ДП60-3 ЭНЕРГЕТИК | CZ6: ДПКР-2 Хайфер, Восх.заря | DA6: ДП60-3 1й сух, Восх. Заря | DB6: ДПКР-2, Калф, Восх.заря | DC6: ДП60-3 дойное, Восх.заря | DD6: ДП60-3 НОВОТЕЛ, Восх.заря | DE6: ДП60-3 2й сух, Восх.заря | DF6: ДП60-3 2й сух, Бакуново | DG6: ДП60-3 1й сух, С-з Минский | DH6: ДП60-3 2й сух, С-з Минский | DI6: ДП60-3 НОВОТЕЛ, С-з Минский | DJ6: ДП60-3 Мумуша, дойное (ДейриБаланс) Макарово, БИРЖА | DK6: ДПКР-2, в к/к ФХ Юлиан | DL6: ДП60-3 дойное, с-з Минский | DM6: ДП60-3 дойное, Бакуново | DN6: ДП60-3 1й сух, Савушкино | DO6: ДП60-3 2й сух, Савушкино | DP6: ДП60-3 НОВОТЕЛ, Савушкино | DQ6: ДПКР-2, Орешковичи | DR6: ДП60-3 транзит, в к/к Сестричество | DU6: ДП60-3 дойное, ФХ Юлиан | DV6: ДП60-3 дойное, Киселевцы | DW6: ДП60-3 2й сух, Киселевцы | DX6: ДПКР-2 Хайфер, ФХ Юлиан | DY6: ДП60-3 1й сух, ФХ Юлиан | DZ6: ДП60-3 Анионные соли, Киселевцы | EA6: ДП60-3 2й сух, Видомлянское | EB6: ДП60-3 дойное, Савушкина пуща | EC6: ДП60-3 1й сух, Осовецкий | ED6: ДП60-3 2й сух, Осовецкий | EE6: ДП60-3 НОВОТЕЛ, Осовецкий | EF6: ДП60-3 НОВОТЕЛ, Орешковичи | EG6: ДП60-3 2й сух, Припять-2009, БИРЖА | EH6: ДП60-3 дойное Мумуша, Агро-Детковичи, БИРЖА | EI6: ДП60-3 1й сух, Утес | EJ6: ДП60-3 2й сух, Утес | EK6: ДП60-3 2й сух, Бакуново | EL6: ДП60-3 2й сух, Лебедева Ветка | EM6: ДПКР-1, Мумуша в к/к Восх.заря | EN6: ДП60-3 НОВОТЕЛ, Савушкина пуща | EO6: ДП60-3 1й сух, Савушкина пуща | EP6: ДП60-3 2й сух, Савушкина пуща | EQ6: ДП60-3 дойное, Агро-Солы | ER6: ДПКР-1 Мумуша в к/к КАЗАХСТАН | ES6: ДП60-3 2й сух, Савушкина пуща | ET6: ДП60-3 НОВОТЕЛ, ФХ Юлиан | EU6: ДП60-3 2й сух, ФХ Юлиан | EV6: ДП60-3 2й сух, Восх.заря | EW6: ДПКР-2, Калф, Восх.заря | EX6: ДП60-3 дойное, Восх.заря | EY6: ДП60-3 1й сух, Восх. Заря | EZ6: ДП60-3 НОВОТЕЛ, КАЗАХСТАН | FA6: ДПКР-2, КАЗАХСТАН | FB6: ДП60-3 2й сух, Свитязянка | FC6: ДП60-3 дойное, Осовецкий | FD6: ДП60-3 НОВОТЕЛ, Восх.заря | FE6: ДПКР-2 Хайфер, ФХ Юлиан | FF6: ДП60-3 дойное, Киселевцы | FG6: ДП60-3 дойное МУМУША, Видомлянское | FH6: ДП60-3 Биохром, ФХ Юлиан | FI6: ДП60-3 дойное, Киселевцы | FJ6: ДП60-3 дойное, Савушкина пуща (склад) | FK6: ДП60-3 дойное, Бакуново | FL6: ДП60-3 1й сух, Неверовичи | FM6: ДП60-3 1й сух, Шапчицы | FN6: ДП60-3 АС, 1 Мая | FO6: ДП60-3 НОВОТЕЛ, Неверовичи | FP6: ДП60-3 дойное Мумуша, Лебедева Ветка, БИРЖА | FQ6: ДП60-3 дойное Мумуша, Лебедева Ветка, БИРЖА | FR6: ДП60-3 1й сух, Лебедева Ветка, БИРЖА | FS6: ДП60-3 2й сух, Лебедева Ветка, БИРЖА | FT6: ДП60-3 2й сух, Припять-2009, БИРЖА | GO6: Отгрузка
B7: дата выработки/планирования | C7: 2025 | D7: 2026 | H7: 46082 | I7: 46112 | K7: 46027 | L7: 46028 | M7: 46030 | N7: 46031 | O7: 46031 | P7: 46031 | Q7: 46031 | R7: 46034 | S7: 46035 | T7: 46035 | U7: 46035 | V7: 46036 | W7: 46036 | X7: 46037 | Y7: 46038 | Z7: 46041 | AA7: 46041 | AB7: 46042 | AC7: 46043 | AD7: 46044 | AE7: 46044 | AF7: 46044 | AG7: 46044 | AH7: 46045 | AI7: 46048 | AJ7: 46048 | AK7: 46048 | AL7: 46048 | AM7: 46049 | AN7: 46049 | AO7: 46049 | AP7: 46049 | AQ7: 46049 | AR7: 46050 | AS7: 46050 | AT7: 46050 | AU7: 46050 | AV7: 46050 | AW7: 46050 | AX7: 46050 | AY7: 46051 | AZ7: 46051 | BA7: 46051 | BB7: 46051 | BC7: 46051 | BD7: 46051 | BE7: 46051 | BF7: 46051 | BG7: 46052 | BH7: 46052 | BI7: 46052 | BJ7: январь | BL7: 46055 | BM7: 46055 | BN7: 46056 | BO7: 46056 | BP7: 46056 | BQ7: 46056 | BR7: 46057 | BS7: 46058 | BT7: 46058 | BU7: 46059 | BV7: 46059 | BW7: 46059 | BX7: 46059 | BY7: 46059 | BZ7: 46059 | CA7: 46059 | CB7: 46062 | CC7: 46062 | CD7: 46062 | CE7: 46063 | CF7: 46063 | CG7: 46064 | CH7: 46064 | CI7: 46064 | CJ7: 46065 | CK7: 46066 | CL7: 46066 | CM7: 46066 | CN7: 46066 | CO7: 46069 | CP7: 46069 | CQ7: 46069 | CR7: 46069 | CS7: 46069 | CT7: 46070 | CU7: 46071 | CV7: 46071 | CW7: 46071 | CX7: 46072 | CY7: 46072 | CZ7: 46073 | DA7: 46073 | DB7: 46073 | DC7: 46073 | DD7: 46076 | DE7: 46076 | DF7: 46076 | DG7: 46076 | DH7: 46076 | DI7: 46076 | DJ7: 46077 | DK7: 46077 | DL7: 46077 | DM7: 46078 | DN7: 46079 | DO7: 46079 | DP7: 46079 | DQ7: 46079 | DR7: 46079 | DS7: февраль | DU7: 46083 | DV7: 46084 | DW7: 46084 | DX7: 46085 | DY7: 46085 | DZ7: 46086 | EA7: 46086 | EB7: 46087 | EC7: 46092 | ED7: 46092 | EE7: 46092 | EF7: 46092 | EG7: 46092 | EH7: 46092 | EI7: 46092 | EJ7: 46092 | EK7: 46093 | EL7: 46093 | EM7: 46093 | EN7: 46094 | EO7: 46097 | EP7: 46098 | EQ7: 46098 | ER7: 46098 | ES7: 46099 | ET7: 46099 | EU7: 46099 | EV7: 46099 | EW7: 46099 | EX7: 46100 | EY7: 46100 | EZ7: 46101 | FA7: 46104 | FB7: 46104 | FC7: 46104 | FD7: 46104 | FE7: 46105 | FF7: 46105 | FG7: 46106 | FH7: 46106 | FI7: 46106 | FJ7: 46107 | FK7: 46108 | FL7: 46108 | FM7: 46108 | FN7: 46108 | FO7: 46111 | FP7: 46111 | FQ7: 46112 | FR7: 46112 | FS7: 46112 | FT7: 46112 | FU7: март | GR7: =I7 -> 46112
B8: Выработка, т | C8: 154.95 | D8: =BJ8 -> 113.2 | E8: =DS8 -> 148.8 | F8: =FU8 -> 108.2 | K8: =1*3 -> 3 | L8: 3 | M8: =1*8 -> 8 | N8: 3.5 | O8: 0.8 | P8: =1 -> 1 | Q8: 1.5 | R8: =1*3 -> 3 | S8: =1*1.6 -> 1.6 | T8: 1 | U8: =1*1.5 -> 1.5 | V8: =1*4 -> 4 | W8: =1*1.5 -> 1.5 | X8: =1*7 -> 7 | Y8: =1*3 -> 3 | Z8: =1*2 -> 2 | AA8: =1*4 -> 4 | AB8: =1*8 -> 8 | AC8: =1*6 -> 6 | AD8: 0.6 | AE8: 1.2 | AF8: 0.8 | AG8: 0.8 | AH8: 3 | AI8: =1*4 -> 4 | AJ8: 2.3 | AK8: 1 | AL8: 0.6 | AM8: 0.8 | AN8: 1 | AO8: =1*2 -> 2 | AP8: =1*1.3 -> 1.3 | AQ8: 0.9 | AR8: 0.4 | AS8: 0.6 | AT8: 1 | AU8: 1 | AV8: =1 -> 1 | AW8: 3 | AX8: =1*1.2 -> 1.2 | AY8: 1.5 | AZ8: 2 | BA8: 2 | BB8: 1 | BC8: =0.3 -> 0.3 | BD8: =0.3/0.3 -> 1 | BE8: 1.5 | BF8: 0.3 | BG8: =10 -> 10 | BH8: =1*0.6 -> 0.6 | BI8: =1*1.1 -> 1.1 | BJ8: =SUM(K8:BI8) -> 113.2 | BL8: 5 | BM8: =1*2.5 -> 2.5 | BN8: =1*1.5 -> 1.5 | BO8: =1*2.4 -> 2.4 | BP8: 1 | BQ8: =1*3 -> 3 | BR8: 5 | BS8: =1*5.4 -> 5.4 | BT8: 3 | BU8: =1*1.9 -> 1.9 | BV8: 0.5 | BW8: 0.3 | BX8: =1*2.1 -> 2.1 | BY8: =1*2 -> 2 | BZ8: 1 | CA8: =1*4 -> 4 | CB8: =1*3 -> 3 | CC8: =1.2/1.2*3 -> 3 | CD8: =1*4 -> 4 | CE8: 1 | CF8: =8/8*6 -> 6 | CG8: 0.3 | CH8: =1*0.6 -> 0.6 | CI8: 1.5 | CJ8: 3 | CK8: =0.8/0.8*0.9 -> 0.9 | CL8: =0.6/0.6*0.9 -> 0.9 | CM8: 0.6 | CN8: 3.5 | CO8: =1*2 -> 2 | CP8: =1*0.3 -> 0.3 | CQ8: 3 | CR8: 1 | CS8: 2 | CT8: 9 | CU8: 4 | CV8: 5 | CW8: 3 | CX8: =10 -> 10 | CY8: 0.1 | CZ8: =0.8/0.8*3 -> 3 | DA8: =1.3/1.3*1.5 -> 1.5 | DB8: =1*2 -> 2 | DC8: =4/4*4.5 -> 4.5 | DD8: 3 | DE8: 1 | DF8: =1*0.6 -> 0.6 | DG8: 1 | DH8: =1 -> 1 | DI8: =8/8 -> 1 | DJ8: =1.6/1.6*1.5 -> 1.5 | DK8: 0.3 | DL8: =1*3 -> 3 | DM8: =1*3 -> 3 | DN8: 1 | DO8: =1*4 -> 4 | DP8: =8/8*7.5 -> 7.5 | DQ8: =1*1.5 -> 1.5 | DR8: 0.1 | DS8: =SUM(BL8:DR8) -> 148.8 | DU8: 2.4 | DV8: 1.5 | DW8: 0.3 | DX8: =0.8/0.8*0.9 -> 0.9 | DY8: =1*1.3 -> 1.3 | DZ8: 0.3 | EA8: 3.6 | EB8: =1*10 -> 10 | EC8: 1 | ED8: 0.6 | EE8: 0.4 | EF8: 1 | EG8: =0.3/0.3*0.6 -> 0.6 | EH8: 0.3 | EI8: =1*0.8 -> 0.8 | EJ8: =1*1.5 -> 1.5 | EK8: 1 | EL8: 1 | EM8: 3 | EN8: =8/8*5 -> 5 | EO8: =1*5 -> 5 | EP8: =1*2 -> 2 | EQ8: 3 | ER8: =1*0.3 -> 0.3 | ES8: =1*3 -> 3 | ET8: 0.6 | EU8: 0.9 | EV8: 0.5 | EW8: =1*2 -> 2 | EX8: =4/4*5 -> 5 | EY8: =1.3/1.3*2 -> 2 | EZ8: 5 | FA8: 2 | FB8: =0.6/0.6*1.2 -> 1.2 | FC8: 3 | FD8: 3 | FE8: =0.8/0.8*2.5 -> 2.5 | FF8: =1.5/1.5*1.1 -> 1.1 | FG8: 4 | FH8: =0.3/0.3*0.1 -> 0.1 | FI8: =1.5/1.5*0.6 -> 0.6 | FJ8: =1*10 -> 10 | FK8: 3 | FL8: =1*0.7 -> 0.7 | FM8: 1 | FN8: =0.5/0.5*0.6 -> 0.6 | FO8: =1*1.2 -> 1.2 | FP8: =3 -> 3 | FQ8: =3 -> 3 | FR8: 0.8 | FS8: =1 -> 1 | FT8: =0.3/0.3*0.6 -> 0.6 | FU8: =SUM(DU8:FT8) -> 108.2 | GP8: =SUM(FW8:GO8) -> 0
A9: 1 | B9: вит А 1000 | C9: 90.47 | D9: =29.41+30.6 -> 60.01 | E9: 87.74 | F9: =63.591 -> 63.591 | G9: =ROUND(AVERAGE(D9:F9),3) -> 70.447 | H9: 81.66 | I9: =18.069+75+125 -> 218.069 | K9: =0.675*3 -> 2.025 | L9: 2.026 | M9: =0.842*8 -> 6.736 | N9: 0.882 | O9: 0.528 | P9: =0.202 -> 0.202 | R9: =0.181*3 -> 0.543 | T9: =0.66 -> 0.66 | U9: =0.181*1.5 -> 0.2715 | V9: =0.181*4 -> 0.724 | W9: =0.675*1.5 -> 1.0125 | X9: =0.181*7 -> 1.267 | Z9: =0.181*2 -> 0.362 | AA9: =0.181*4 -> 0.724 | AB9: =0.181*8 -> 1.448 | AC9: =0.842*6 -> 5.052 | AE9: 1.572 | AF9: 0.14 | AG9: 0.14 | AH9: 0.544 | AI9: =1.008*4 -> 4.032 | AJ9: 6.028 | AK9: 0.302 | AL9: 0.109 | AM9: 0.427 | AN9: 0.706 | AO9: =0.534*2 -> 1.068 | AP9: =0.66*1.3 -> 0.858 | AQ9: 0.163 | AR9: 0.07 | AS9: 0.105 | AT9: 2.621 | AU9: 0.181 | AV9: =0.66 -> 0.66 | AW9: 2.026 | AX9: =0.675*1.2 -> 0.81 | AY9: 1.966 | AZ9: 0.308 | BA9: 0.31 | BB9: 0.181 | BD9: =0.198/0.3 -> 0.66 | BE9: 0.378 | BF9: 0.151 | BG9: =8.417 -> 8.417 | BH9: =0.66*0.6 -> 0.396 | BI9: =0.181*1.1 -> 0.1991 | BJ9: =SUM(K9:BI9) -> 59.9911 | BL9: 2.52 | BN9: =0.66*1.5 -> 0.99 | BO9: =0.675*2.4 -> 1.62 | BP9: 0.66 | BQ9: =0.675*3 -> 2.025 | BS9: =0.181*5.4 -> 0.9774 | BT9: 2.026 | BU9: =0.675*1.9 -> 1.2825 | BV9: 0.33 | BW9: 0.172 | BX9: =0.181*2.1 -> 0.3801 | BY9: =0.181*2 -> 0.362 | BZ9: =0.66 -> 0.66 | CA9: =0.181*4 -> 0.724 | CB9: =0.675*3 -> 2.025 | CC9: =0.81/1.2*3 -> 2.025 | CD9: =0.181*4 -> 0.724 | CE9: 0.66 | CF9: =1.452/8*6 -> 1.089 | CG9: 0.198 | CH9: =0.202*0.6 -> 0.1212 | CK9: =0.427/0.8*0.9 -> 0.480375 | CL9: =0.109/0.6*0.9 -> 0.1635 | CM9: 0.109 | CN9: 0.882 | CO9: =0.181*2 -> 0.362 | CP9: =0.66*0.3 -> 0.198 | CQ9: 2.026 | CR9: 0.66 | CS9: 3.024 | CT9: 23.587 | CU9: 2.867 | CV9: 1.008 | CW9: 4.536 | CX9: =8.417 -> 8.417 | CY9: 0.111 | CZ9: =0.427/0.8*3 -> 1.60125 | DA9: =0.858/1.3*1.5 -> 0.99 | DB9: =0.302*2 -> 0.604 | DC9: =4.032/4*4.5 -> 4.536 | DD9: 0.544 | DE9: 0.706 | DF9: =0.181*0.6 -> 0.1086 | DG9: =0.66 -> 0.66 | DH9: =0.181 -> 0.181 | DI9: =1.452/8 -> 0.1815 | DK9: 0.151 | DL9: =0.675*3 -> 2.025 | DM9: =0.675*3 -> 2.025 | DN9: =0.66 -> 0.66 | DO9: =0.181*4 -> 0.724 | DP9: =1.452/8*7.5 -> 1.36125 | DQ9: =0.383*1.5 -> 0.5745 | DR9: 0.06 | DS9: =SUM(BL9:DR9) -> 87.695175 | DU9: 1.621 | DV9: 1.013 | DW9: 0.198 | DX9: =0.427/0.8*0.9 -> 0.480375 | DY9: =0.66*1.3 -> 0.858 | EA9: =0.726 -> 0.726 | EB9: =0.842*10 -> 8.42 | EC9: 2.621 | ED9: 0.105 | EE9: 0.07 | EF9: 0.181 | EG9: =0.172/0.3*0.6 -> 0.344 | EH9: 0.203 | EI9: =0.66*0.8 -> 0.528 | EJ9: =0.181*1.5 -> 0.2715 | EK9: 0.181 | EL9: 0.181 | EM9: 0.756 | EN9: =1.452/8*5 -> 0.9075 | EO9: =0.66*5 -> 3.3 | EP9: =0.181*2 -> 0.362 | EQ9: 2.026 | ER9: =0.252*0.3 -> 0.0756 | ES9: =0.181*3 -> 0.543 | ET9: 0.109 | EU9: 0.163 | EV9: 0.353 | EW9: =0.302*2 -> 0.604 | EX9: =4.032/4*5 -> 5.04 | EY9: =0.858/1.3*2 -> 1.32 | EZ9: 1.008 | FA9: 3.024 | FB9: =0.121/0.6*1.2 -> 0.242 | FC9: 3.024 | FD9: 0.544 | FE9: =0.427/0.8*2.5 -> 1.334375 | FF9: =1.013/1.5*1.1 -> 0.74286667 | FG9: 2.701 | FH9: =0.003/0.3*0.1 -> 0.001 | FI9: =1.013/1.5*0.6 -> 0.4052 | FJ9: =0.842*10 -> 8.42 | FK9: =2.026 -> 2.026 | FL9: =0.66*0.7 -> 0.462 | FM9: 0.66 | FN9: =0.101/0.5*0.6 -> 0.1212 | FO9: =0.181*1.2 -> 0.2172 | FP9: =2.026 -> 2.026 | FQ9: =2.026 -> 2.026 | FR9: 0.528 | FS9: =0.181 -> 0.181 | FT9: =0.172/0.3*0.6 -> 0.344 | FU9: =SUM(DU9:FT9) -> 63.598817 | GP9: =SUM(FW9:GO9) -> 0 | GQ9: =I9-GP9 -> 218.069 | GR9: =I9 -> 218.069 | GS9: =G9 -> 70.447 | GT9: =E9 -> 87.74 | GU9: =B9 -> вит А 1000
A10: =A9+1 -> 2 | B10: вит Д3 500 | C10: =28.8+3.75+5.23 -> 37.78 | D10: =0.01+26.35 -> 26.36 | E10: 36.554 | F10: =31.021+4.2 -> 35.221 | G10: =ROUND(AVERAGE(D10:F10),3) -> 32.712 | H10: 31.866 | I10: =0.845+95.8 -> 96.645 | K10: =0.397*3 -> 1.191 | L10: 1.192 | M10: =0.407*8 -> 3.256 | N10: 0.38 | O10: 0.248 | P10: =0.097 -> 0.097 | Q10: 0.116 | R10: =0.097*3 -> 0.291 | T10: =0.31 -> 0.31 | U10: =0.097*1.5 -> 0.1455 | V10: =0.097*4 -> 0.388 | W10: =0.397*1.5 -> 0.5955 | X10: =0.097*7 -> 0.679 | Z10: =0.097*2 -> 0.194 | AA10: =0.097*4 -> 0.388 | AB10: =0.097*8 -> 0.776 | AC10: =0.407*6 -> 2.442 | AE10: 0.349 | AF10: 0.031 | AG10: 0.031 | AH10: 0.291 | AI10: =0.397*4 -> 1.588 | AJ10: 1.56 | AK10: 0.165 | AL10: 0.058 | AM10: 0.155 | AN10: =0.3+0.01 -> 0.31 | AO10: =0.194*2 -> 0.388 | AP10: =0.31*1.3 -> 0.403 | AQ10: 0.087 | AR10: 0.016 | AS10: 0.023 | AT10: 0.582 | AU10: 0.097 | AV10: =0.31 -> 0.31 | AW10: 1.192 | AX10: =0.397*1.2 -> 0.4764 | AY10: 0.436 | AZ10: 0.07 | BA10: 0.07 | BB10: 0.097 | BC10: =0.024 -> 0.024 | BD10: =0.093/0.3 -> 0.31 | BE10: 0.087 | BF10: 0.074 | BG10: =4.071 -> 4.071 | BH10: =0.31*0.6 -> 0.186 | BI10: =0.097*1.1 -> 0.1067 | BJ10: =SUM(K10:BI10) -> 26.3331 | BL10: 0.649 | BN10: =0.31*1.5 -> 0.465 | BO10: =0.397*2.4 -> 0.9528 | BP10: 0.31 | BQ10: =0.397*3 -> 1.191 | BS10: =0.097*5.4 -> 0.5238 | BT10: 1.192 | BU10: =0.397*1.9 -> 0.7543 | BV10: 0.155 | BW10: 0.081 | BX10: =0.097*2.1 -> 0.2037 | BY10: =0.097*2 -> 0.194 | BZ10: =0.31 -> 0.31 | CA10: =0.097*4 -> 0.388 | CB10: =0.397*3 -> 1.191 | CC10: =0.477/1.2*3 -> 1.1925 | CD10: =0.097*4 -> 0.388 | CE10: 0.31 | CF10: =0.775/8*6 -> 0.58125 | CG10: 0.093 | CH10: =0.097*0.6 -> 0.0582 | CI10: 0.116 | CK10: =0.155/0.8*0.9 -> 0.174375 | CL10: =0.058/0.6*0.9 -> 0.087 | CM10: 0.058 | CN10: 0.38 | CO10: =0.097*2 -> 0.194 | CP10: =0.31*0.3 -> 0.093 | CQ10: 1.192 | CR10: 0.31 | CS10: 1.473 | CT10: 5.234 | CU10: 1.093 | CV10: 0.262 | CW10: 2.21 | CX10: =4.071 -> 4.071 | CY10: 0.004 | CZ10: =0.155/0.8*3 -> 0.58125 | DA10: =0.403/1.3*1.5 -> 0.465 | DB10: =0.165*2 -> 0.33 | DC10: =1.59/4*4.5 -> 1.78875 | DD10: 0.291 | DE10: =0.3+0.01 -> 0.31 | DF10: =0.097*0.6 -> 0.0582 | DG10: =0.31 -> 0.31 | DH10: =0.097 -> 0.097 | DI10: =0.775/8 -> 0.096875 | DK10: 0.074 | DL10: =0.397*3 -> 1.191 | DM10: =0.397*3 -> 1.191 | DN10: =0.31 -> 0.31 | DO10: =0.097*4 -> 0.388 | DP10: =0.775/8*7.5 -> 0.7265625 | DQ10: =0.136*1.5 -> 0.204 | DR10: 0.019 | DS10: =SUM(BL10:DR10) -> 36.566563 | DU10: 0.954 | DV10: 0.596 | DW10: 0.093 | DX10: =0.155/0.8*0.9 -> 0.174375 | DY10: =0.31*1.3 -> 0.403 | EA10: =0.465 -> 0.465 | EB10: =0.407*10 -> 4.07 | EC10: 0.582 | ED10: 0.023 | EE10: 0.016 | EF10: 0.097 | EG10: =0.081/0.3*0.6 -> 0.162 | EH10: 0.119 | EI10: =0.31*0.8 -> 0.248 | EJ10: =0.097*1.5 -> 0.1455 | EK10: 0.097 | EL10: 0.097 | EM10: 0.174 | EN10: =0.775/8*5 -> 0.484375 | EO10: =0.31*5 -> 1.55 | EP10: =0.097*2 -> 0.194 | EQ10: 1.192 | ER10: =0.058*0.3 -> 0.0174 | ES10: =0.097*3 -> 0.291 | ET10: 0.058 | EU10: 0.087 | EV10: 0.155 | EW10: =0.165*2 -> 0.33 | EX10: =1.59/4*5 -> 1.9875 | EY10: =0.403/1.3*2 -> 0.62 | EZ10: 0.262 | FA10: 1.473 | FB10: =0.058/0.6*1.2 -> 0.116 | FC10: 5.815 | FD10: 0.291 | FE10: =0.155/0.8*2.5 -> 0.484375 | FF10: =0.596/1.5*1.1 -> 0.43706667 | FG10: 1.59 | FH10: =0.003/0.3*0.1 -> 0.001 | FI10: =0.596/1.5*0.6 -> 0.2384 | FJ10: =0.407*10 -> 4.07 | FK10: =1.24 -> 1.24 | FL10: =0.31*0.7 -> 0.217 | FM10: 0.31 | FN10: =0.048/0.5*0.6 -> 0.0576 | FO10: =0.101*1.2 -> 0.1212 | FP10: =1.24 -> 1.24 | FQ10: =1.24 -> 1.24 | FR10: 0.258 | FS10: =0.101 -> 0.101 | FT10: =0.081/0.3*0.6 -> 0.162 | FU10: =SUM(DU10:FT10) -> 35.206792 | GP10: =SUM(FW10:GO10) -> 0 | GQ10: =I10-GP10 -> 96.645 | GR10: =I10 -> 96.645 | GS10: =G10 -> 32.712 | GT10: =E10 -> 36.554 | GU10: =B10 -> вит Д3 500
A11: =A10+1 -> 3 | B11: вит Е 50% | C11: =31.74+876.66+187.87 -> 1096.27 | D11: =835.24 -> 835.24 | E11: =472.08+568.9 -> 1040.98 | F11: =4.81+973.35 -> 978.16 | G11: =ROUND(AVERAGE(D11:F11),3) -> 951.46 | H11: =4.81+1431.1 -> 1435.91 | I11: =457.75+2000 -> 2457.75 | K11: =8.971*3 -> 26.913 | L11: 26.914 | M11: =12.096*8 -> 96.768 | N11: 9.878 | O11: 8.064 | P11: =9.193 -> 9.193 | Q11: 4.234 | R11: =9.475*3 -> 28.425 | T11: =19.152 -> 19.152 | U11: =2.419*1.5 -> 3.6285 | V11: =9.475*4 -> 37.9 | W11: =8.971*1.5 -> 13.4565 | X11: =2.419*7 -> 16.933 | Y11: =2.016*3 -> 6.048 | Z11: =2.419*2 -> 4.838 | AA11: =9.475*4 -> 37.9 | AB11: =2.419*8 -> 19.352 | AC11: =12.096*6 -> 72.576 | AD11: 0.161 | AE11: 1.814 | AF11: 0.323 | AG11: 0.161 | AH11: 7.258 | AI11: =8.971*4 -> 35.884 | AJ11: 9.274 | AK11: 8.064 | AL11: 1.452 | AM11: 8.064 | AN11: 19.152 | AO11: =10.08*2 -> 20.16 | AP11: =19.152*1.3 -> 24.8976 | AQ11: 8.528 | AR11: 0.161 | AS11: 0.121 | AT11: 3.024 | AU11: 9.475 | AV11: =19.152 -> 19.152 | AW11: 26.914 | AX11: =8.971*1.2 -> 10.7652 | AY11: 2.268 | AZ11: 0.71 | BA11: 0.355 | BB11: 2.419 | BC11: =2.298 -> 2.298 | BD11: =5.746/0.3 -> 19.153333 | BE11: 8.017 | BF11: 0.202 | BG11: =120.96 -> 120.96 | BH11: =19.152*0.6 -> 11.4912 | BI11: =9.475*1.1 -> 10.4225 | BJ11: =SUM(K11:BI11) -> 835.27383 | BL11: 20.16 | BN11: =19.152*1.5 -> 28.728 | BO11: =8.971*2.4 -> 21.5304 | BP11: 19.152 | BQ11: =8.971*3 -> 26.913 | BR11: 15.12 | BS11: =2.419*5.4 -> 13.0626 | BT11: 26.914 | BU11: =8.971*1.9 -> 17.0449 | BV11: 9.576 | BW11: 3.145 | BX11: =2.419*2.1 -> 5.0799 | BY11: =2.419*2 -> 4.838 | BZ11: 23.99 | CA11: =9.475*4 -> 37.9 | CB11: =8.971*3 -> 26.913 | CC11: =10.765/1.2*3 -> 26.9125 | CD11: =9.475*4 -> 37.9 | CE11: 19.152 | CF11: =19.354/8*6 -> 14.5155 | CG11: 3.024 | CH11: =9.193*0.6 -> 5.5158 | CI11: 4.234 | CJ11: 6.048 | CK11: =7.906/0.8*0.9 -> 8.89425 | CL11: =5.574/0.6*0.9 -> 8.361 | CM11: 1.452 | CN11: 9.878 | CO11: =2.372*2 -> 4.744 | CP11: =19.152*0.3 -> 5.7456 | CQ11: 26.386 | CR11: 23.52 | CS11: 4.032 | CT11: 27.234 | CU11: 45.467 | CV11: 9.882 | CW11: 5.929 | CX11: 118.588 | CY11: 0.484 | CZ11: =7.906/0.8*3 -> 29.6475 | DA11: =24.409/1.3*1.5 -> 28.164231 | DB11: =7.906*2 -> 15.812 | DC11: =35.181/4*4.5 -> 39.578625 | DD11: 7.115 | DE11: 18.776 | DF11: =9.475*0.6 -> 5.685 | DG11: 23.52 | DH11: =9.289 -> 9.289 | DI11: =18.974/8 -> 2.37175 | DK11: 0.202 | DL11: =8.795*3 -> 26.385 | DM11: =8.795*3 -> 26.385 | DN11: 23.52 | DO11: =9.289*4 -> 37.156 | DP11: =18.974/8*7.5 -> 17.788125 | DQ11: =7.511*1.5 -> 11.2665 | DR11: 0.356 | DS11: =SUM(BL11:DR11) -> 1040.9832 | DU11: =16.393+4.81 -> 21.203 | DV11: 13.193 | DW11: 5.633 | DX11: =7.906/0.8*0.9 -> 8.89425 | DY11: =18.776*1.3 -> 24.4088 | DZ11: 0.889 | EA11: =5.218 -> 5.218 | EB11: =11.859*10 -> 118.59 | EC11: 2.965 | ED11: 0.237 | EE11: 0.079 | EF11: 2.372 | EG11: =3.083/0.3*0.6 -> 6.166 | EH11: 2.639 | EI11: =23.52*0.8 -> 18.816 | EJ11: =9.289*1.5 -> 13.9335 | EK11: 9.289 | EL11: 9.289 | EM11: 15.719 | EN11: =18.974/8*5 -> 11.85875 | EO11: =23.52*5 -> 117.6 | EP11: =9.289*2 -> 18.578 | EQ11: 26.386 | ER11: =5.24*0.3 -> 1.572 | ES11: =9.289*3 -> 27.867 | ET11: 1.423 | EU11: 8.36 | EV11: 9.388 | EW11: =7.906*2 -> 15.812 | EX11: =35.181/4*5 -> 43.97625 | EY11: =24.409/1.3*2 -> 37.552308 | EZ11: 9.882 | FA11: 3.953 | FB11: =5.408/0.6*1.2 -> 10.816 | FD11: 7.115 | FE11: =7.906/0.8*2.5 -> 24.70625 | FF11: =13.193/1.5*1.1 -> 9.6748667 | FG11: 35.181 | FH11: =0.059/0.3*0.1 -> 0.019666667 | FI11: =13.193/1.5*0.6 -> 5.2772 | FJ11: =11.859*10 -> 118.59 | FK11: =26.386 -> 26.386 | FL11: =23.52*0.7 -> 16.464 | FM11: 18.776 | FN11: =4.447/0.5*0.6 -> 5.3364 | FO11: =2.372*1.2 -> 2.8464 | FP11: =26.386 -> 26.386 | FQ11: =26.386 -> 26.386 | FR11: 15.021 | FS11: =9.289 -> 9.289 | FT11: =3.083/0.3*0.6 -> 6.166 | FU11: =SUM(DU11:FT11) -> 978.17864 | GP11: =SUM(FW11:GO11) -> 0 | GQ11: =I11-GP11 -> 2457.75 | GR11: =I11 -> 2457.75 | GS11: =G11 -> 951.46 | GT11: =E11 -> 1040.98 | GU11: =B11 -> вит Е 50%
A12: =A11+1 -> 4 | B12: вит В1 (тиамин) | C12: 0 | D12: 0 | E12: 0 | F12: 0 | G12: =ROUND(AVERAGE(D12:F12),3) -> 0 | H12: 0 | I12: 0 | BJ12: =SUM(K12:BI12) -> 0 | DS12: =SUM(BL12:DR12) -> 0 | FU12: =SUM(DU12:FT12) -> 0 | GP12: =SUM(FW12:GO12) -> 0 | GQ12: =I12-GP12 -> 0 | GR12: =I12 -> 0 | GS12: =G12 -> 0 | GT12: =E12 -> 0 | GU12: =B12 -> вит В1 (тиамин)
A13: =A12+1 -> 5 | B13: вит В2 | C13: 0.71 | D13: 0.52 | E13: 0.73 | F13: 0.04 | G13: =ROUND(AVERAGE(D13:F13),3) -> 0.43 | H13: 0.04 | I13: 0 | BE13: 0.019 | BG13: =0.504 -> 0.504 | BJ13: =SUM(K13:BI13) -> 0.523 | BN13: =0.05*1.5 -> 0.075 | BO13: =0.05*2.4 -> 0.12 | BQ13: =0.05*3 -> 0.15 | CP13: =0.05*0.3 -> 0.015 | CX13: 0.36 | DS13: =SUM(BL13:DR13) -> 0.72 | EM13: 0.04 | FU13: =SUM(DU13:FT13) -> 0.04 | GP13: =SUM(FW13:GO13) -> 0 | GQ13: =I13-GP13 -> 0 | GR13: =I13 -> 0 | GS13: =G13 -> 0.43 | GT13: =E13 -> 0.73 | GU13: =B13 -> вит В2 | GV13: 46133
A14: =A13+1 -> 6 | B14: вит В3, Нутравит В5 (кальпан) | C14: 0.25 | D14: 0.08 | E14: 0 | F14: 0.17 | G14: =ROUND(AVERAGE(D14:F14),3) -> 0.083 | H14: 14.29 | I14: 14.12 | BE14: 0.077 | BJ14: =SUM(K14:BI14) -> 0.077 | DS14: =SUM(BL14:DR14) -> 0 | EM14: 0.154 | ER14: =0.051*0.3 -> 0.0153 | FU14: =SUM(DU14:FT14) -> 0.1693 | GP14: =SUM(FW14:GO14) -> 0 | GQ14: =I14-GP14 -> 14.12 | GR14: =I14 -> 14.12 | GS14: =G14 -> 0.083 | GT14: =E14 -> 0 | GU14: =B14 -> вит В3, Нутравит В5 (кальпан) | GV14: 46455 | GW14: =GQ14/GT14 -> #DIV/0!
A15: =A14+1 -> 7 | B15: вит В5 (ниацин) | C15: 0.53 | D15: 0.23 | E15: 0 | F15: 0.51 | G15: =ROUND(AVERAGE(D15:F15),3) -> 0.247 | H15: 19.977 | I15: 19.467 | BE15: 0.229 | BJ15: =SUM(K15:BI15) -> 0.229 | DS15: =SUM(BL15:DR15) -> 0 | EM15: 0.458 | ER15: =0.153*0.3 -> 0.0459 | FU15: =SUM(DU15:FT15) -> 0.5039 | GP15: =SUM(FW15:GO15) -> 0 | GQ15: =I15-GP15 -> 19.467 | GR15: =I15 -> 19.467 | GS15: =G15 -> 0.247 | GT15: =E15 -> 0 | GU15: =B15 -> вит В5 (ниацин) | GV15: 46890 | GW15: =GQ15/GT15 -> #DIV/0!
A16: =A15+1 -> 8 | B16: вит В6 (пиридоксин) | C16: 0.03 | D16: 0.02 | E16: 0.51 | F16: 0.133 | G16: =ROUND(AVERAGE(D16:F16),3) -> 0.221 | H16: 14.1 | I16: 13.967 | BE16: 0.015 | BJ16: =SUM(K16:BI16) -> 0.015 | BL16: 0.509 | DS16: =SUM(BL16:DR16) -> 0.509 | EM16: 0.031 | ER16: =0.01*0.3 -> 0.003 | FS16: =0.102 -> 0.102 | FU16: =SUM(DU16:FT16) -> 0.136 | GP16: =SUM(FW16:GO16) -> 0 | GQ16: =I16-GP16 -> 13.967 | GR16: =I16 -> 13.967 | GS16: =G16 -> 0.221 | GT16: =E16 -> 0.51 | GU16: =B16 -> вит В6 (пиридоксин) | GV16: 46941 | GW16: =GQ16/GT16 -> 27.386275
A17: =A16+1 -> 9 | B17: вит Н (биотин) | C17: =143.25+16.72+111.24 -> 271.21 | D17: =7.13+88.76+139.14 -> 235.03 | E17: 252.97 | F17: 167.52 | G17: =ROUND(AVERAGE(D17:F17),3) -> 218.507 | H17: 307.89 | I17: 140.37 | M17: =5.796*8 -> 46.368 | N17: 7.056 | P17: =2.016 -> 2.016 | Q17: 3.024 | R17: =2.016*3 -> 6.048 | U17: =2.016*1.5 -> 3.024 | V17: =2.016*4 -> 8.064 | X17: =2.016*7 -> 14.112 | Z17: =2.016*2 -> 4.032 | AA17: =2.016*4 -> 8.064 | AB17: =2.016*8 -> 16.128 | AC17: =5.796*6 -> 34.776 | AF17: 0.536 | AG17: 0.536 | AH17: =2.09+3.961 -> 6.051 | AJ17: 3.709 | AL17: 1.21 | AQ17: 1.814 | AR17: 0.268 | AS17: 0.402 | AU17: 2.016 | AZ17: 1.179 | BA17: 1.179 | BB17: 2.016 | BC17: =1.21 -> 1.21 | BG17: =57.96 -> 57.96 | BI17: =2.016*1.1 -> 2.2176 | BJ17: =SUM(K17:BI17) -> 235.0156 | BS17: =2.016*5.4 -> 10.8864 | BX17: =2.016*2.1 -> 4.2336 | BY17: =2.016*2 -> 4.032 | CA17: =2.016*4 -> 8.064 | CD17: =2.016*4 -> 8.064 | CF17: =16.128/8*6 -> 12.096 | CH17: =2.016*0.6 -> 1.2096 | CI17: 3.024 | CL17: =1.21/0.6*0.9 -> 1.815 | CM17: 1.21 | CN17: 7.056 | CO17: =2.016*2 -> 4.032 | CT17: 90.72 | CV17: 3.78 | CX17: =57.96 -> 57.96 | DD17: =2.09+3.961 -> 6.051 | DF17: =2.016*0.6 -> 1.2096 | DH17: =2.016 -> 2.016 | DI17: =16.128/8 -> 2.016 | DO17: =2.016*4 -> 8.064 | DP17: =16.128/8*7.5 -> 15.12 | DR17: 0.318 | DS17: =SUM(BL17:DR17) -> 252.9772 | EA17: =2.413 -> 2.413 | EB17: =5.796*10 -> 57.96 | ED17: 0.402 | EE17: 0.268 | EF17: 2.016 | EJ17: =2.016*1.5 -> 3.024 | EK17: 2.016 | EL17: 2.016 | EN17: =16.128/8*5 -> 10.08 | EP17: =2.016*2 -> 4.032 | ES17: =2.016*3 -> 6.048 | ET17: 1.21 | EU17: 1.814 | EZ17: 3.352 | FB17: =1.21/0.6*1.2 -> 2.42 | FD17: 6.048 | FJ17: =5.796*10 -> 57.96 | FO17: =2.016*1.2 -> 2.4192 | FS17: =2.016 -> 2.016 | FU17: =SUM(DU17:FT17) -> 167.5142 | GP17: =SUM(FW17:GO17) -> 0 | GQ17: =I17-GP17 -> 140.37 | GR17: =I17 -> 140.37 | GS17: =G17 -> 218.507 | GT17: =E17 -> 252.97 | GU17: =B17 -> вит Н (биотин)
H18: =SUM(H9:H17) -> 1905.733 | I18: =SUM(I9:I17) -> 2960.388
A19: =A17+1 -> 10 | B19: окись магния, порошок магнезитовый | C19: =3914.16+10971.21 -> 14885.37 | D19: 10047.63 | E19: 15140.75 | F19: =3840.41+8549.98 -> 12390.39 | G19: =ROUND(AVERAGE(D19:F19),3) -> 12526.257 | H19: =3840.41+20000 -> 23840.41 | I19: 11450.02 | K19: =159.957*3 -> 479.871 | L19: 478.242 | M19: =70.56*8 -> 564.48 | N19: 10.263 | O19: 185.07 | P19: =69.051 -> 69.051 | Q19: 249.458 | R19: =93.283*3 -> 279.849 | T19: =208.128 -> 208.128 | V19: =93.283*4 -> 373.132 | W19: =159.957*1.5 -> 239.9355 | Y19: =18.327*3 -> 54.981 | AA19: =93.283*4 -> 373.132 | AC19: =70.56*6 -> 423.36 | AD19: 16.128 | AE19: 149.551 | AF19: 1.955 | AG19: 1.955 | AH19: 302.204 | AI19: =444.145*4 -> 1776.58 | AJ19: 84.305 | AK19: 91.636 | AL19: 60.441 | AM19: 87.971 | AN19: 208.135 | AO19: =109.964*2 -> 219.928 | AP19: =208.128*1.3 -> 270.5664 | AQ19: 92.344 | AR19: 0.977 | AS19: 1.466 | AT19: 249.251 | AU19: 93.283 | AV19: =208.128 -> 208.128 | AW19: 478.242 | AX19: =159.957*1.2 -> 191.9484 | AY19: 186.938 | AZ19: 4.312 | BA19: 4.312 | BB19: 93.413 | BD19: =62.438/0.3 -> 208.12667 | BE19: 41.236 | BF19: 0.275 | BG19: =705.6 -> 705.6 | BH19: =208.128*0.6 -> 124.8768 | BI19: =93.283*1.1 -> 102.6113 | BJ19: =SUM(K19:BI19) -> 10047.648 | BL19: 606.734 | BN19: =208.128*1.5 -> 312.192 | BO19: =159.414*2.4 -> 382.5936 | BP19: 208.128 | BQ19: =159.957*3 -> 479.871 | BT19: 478.242 | BU19: =159.957*1.9 -> 303.9183 | BV19: 104.064 | BW19: 45.076 | BZ19: =208.128 -> 208.128 | CA19: =93.283*4 -> 373.132 | CB19: =159.957*3 -> 479.871 | CC19: =191.948/1.2*3 -> 479.87 | CD19: =93.283*4 -> 373.132 | CE19: 208.128 | CG19: 69.401 | CH19: =69.051*0.6 -> 41.4306 | CI19: 249.458 | CJ19: 54.982 | CK19: =87.971/0.8*0.9 -> 98.967375 | CL19: =61.563/0.6*0.9 -> 92.3445 | CM19: 60.441 | CN19: 10.263 | CP19: =208.128*0.3 -> 62.4384 | CQ19: 478.242 | CR19: 208.128 | CS19: 5.498 | CT19: 1649.455 | CU19: 997.004 | CV19: 67.444 | CW19: 8.247 | CX19: =705.6 -> 705.6 | CZ19: =87.971/0.8*3 -> 329.89125 | DA19: =270.676/1.3*1.5 -> 312.31846 | DB19: =91.636*2 -> 183.272 | DC19: =1776.813/4*4.5 -> 1998.9146 | DD19: 302.204 | DE19: 208.135 | DF19: =93.283*0.6 -> 55.9698 | DG19: =208.212 -> 208.212 | DH19: =93.347 -> 93.347 | DK19: 0.275 | DL19: =160.014*3 -> 480.042 | DM19: =160.014*3 -> 480.042 | DN19: =208.212 -> 208.212 | DO19: =93.347*4 -> 373.388 | DQ19: =1.833*1.5 -> 2.7495 | DR19: 1.375 | DS19: =SUM(BL19:DR19) -> 15140.771 | DU19: 382.733 | DV19: 239.964 | DW19: 62.464 | DX19: =87.971/0.8*0.9 -> 98.967375 | DY19: =208.212*1.3 -> 270.6756 | EA19: 8.797 | EB19: =70.56*10 -> 705.6 | EC19: 249.251 | ED19: 1.466 | EE19: 0.977 | EF19: 93.433 | EG19: =45.09/0.3*0.6 -> 90.18 | EH19: 48.004 | EI19: =208.212*0.8 -> 166.5696 | EJ19: =93.347*1.5 -> 140.0205 | EK19: 93.347 | EL19: 93.348 | EM19: 82.473 | EO19: =208.212*5 -> 1041.06 | EP19: =93.347*2 -> 186.694 | EQ19: 478.417 | ER19: =27.491*0.3 -> 8.2473 | ES19: =93.347*3 -> 280.041 | ET19: 60.452 | EU19: 92.38 | EV19: 104.11 | EW19: =91.636*2 -> 183.272 | EX19: =1776.813/4*5 -> 2221.0163 | EY19: =270.676/1.3*2 -> 416.42462 | EZ19: 61.396 | FA19: 5.498 | FB19: =41.461/0.6*1.2 -> 82.922 | FD19: 302.262 | FE19: =87.971/0.8*2.5 -> 274.90938 | FF19: =240.021/1.5*1.1 -> 176.0154 | FG19: 640.057 | FI19: =240.021/1.5*0.6 -> 96.0084 | FJ19: =70.56*10 -> 705.6 | FK19: =480.853 -> 480.853 | FL19: =208.212*0.7 -> 145.7484 | FM19: 208.212 | FP19: =480.042 -> 480.042 | FQ19: =480.042 -> 480.042 | FR19: 166.57 | FS19: =93.652 -> 93.652 | FT19: =45.09/0.3*0.6 -> 90.18 | FU19: =SUM(DU19:FT19) -> 12390.352 | GP19: =SUM(FW19:GO19) -> 0 | GQ19: =I19-GP19 -> 11450.02 | GR19: =I19 -> 11450.02 | GS19: =G19 -> 12526.257 | GT19: =E19 -> 15140.75 | GU19: =B19 -> окись магния, порошок магнезитовый
A20: =A19+1 -> 11 | B20: сульфат магния б/водный, магний с/кисл. | C20: =7803.13+3000+1522.55 -> 12325.68 | D20: 7659.51 | E20: =7767.32+3207.89+655.2 -> 11630.41 | F20: =50.62+6061.38+1679.13 -> 7791.13 | G20: =ROUND(AVERAGE(D20:F20),3) -> 9027.017 | H20: =50.62+13792.11+2000+2344.8 -> 18187.53 | I20: =7730.73+2000+1000+665.67 -> 11396.4 | K20: =98.695*3 -> 296.085 | L20: 301.033 | M20: =65.52*8 -> 524.16 | O20: 43.544 | P20: =87.34 -> 87.34 | Q20: 43.673 | R20: =111.391*3 -> 334.173 | S20: =342.72*1.6 -> 548.352 | T20: =147.236 -> 147.236 | U20: =66.833*1.5 -> 100.2495 | V20: =111.391*4 -> 445.564 | W20: =98.695*1.5 -> 148.0425 | X20: =66.834*7 -> 467.838 | Z20: =66.834*2 -> 133.668 | AA20: =111.391*4 -> 445.564 | AB20: =66.834*8 -> 534.672 | AC20: =65.52*6 -> 393.12 | AH20: 100.251 | AI20: =100.252*4 -> 401.008 | AL20: 20.05 | AN20: 147.236 | AP20: =147.236*1.3 -> 191.4068 | AQ20: 61.138 | AU20: 111.391 | AV20: =147.236 -> 147.236 | AW20: 301.033 | AX20: =98.695*1.2 -> 118.434 | BB20: 33.417 | BC20: =19.312 -> 19.312 | BD20: =44.171/0.3 -> 147.23667 | BG20: =655.2 -> 655.2 | BH20: =147.236*0.6 -> 88.3416 | BI20: =111.391*1.1 -> 122.5301 | BJ20: =SUM(K20:BI20) -> 7659.5352 | BL20: 383.958 | BM20: =342.72*2.5 -> 856.8 | BN20: =147.236*1.5 -> 220.854 | BO20: =100.344*2.4 -> 240.8256 | BP20: 147.236 | BQ20: =98.695*3 -> 296.085 | BR20: 886.669 | BS20: =66.834*5.4 -> 360.9036 | BT20: 301.033 | BU20: =98.695*1.9 -> 187.5205 | BV20: 73.618 | BW20: 23.417 | BX20: =66.834*2.1 -> 140.3514 | BY20: =66.833*2 -> 133.666 | BZ20: =147.236 -> 147.236 | CA20: =111.391*4 -> 445.564 | CB20: =98.695*3 -> 296.085 | CC20: =118.433/1.2*3 -> 296.0825 | CD20: =111.391*4 -> 445.564 | CE20: 147.236 | CF20: =534.667/8*6 -> 401.00025 | CG20: 16.329 | CH20: =87.34*0.6 -> 52.404 | CI20: 43.673 | CL20: =40.759/0.6*0.9 -> 61.1385 | CM20: 20.05 | CO20: =66.833*2 -> 133.666 | CP20: =147.236*0.3 -> 44.1708 | CQ20: 301.033 | CR20: 147.236 | CV20: 201.6 | CX20: =655.2 -> 655.2 | DA20: =192.131/1.3*1.5 -> 221.68962 | DC20: =402.523/4*4.5 -> 452.83838 | DD20: 100.251 | DE20: 147.236 | DF20: =111.391*0.6 -> 66.8346 | DG20: =147.793 -> 147.793 | DH20: =111.812 -> 111.812 | DI20: =536.689/8 -> 67.086125 | DJ20: =548.352/1.6*1.5 -> 514.08 | DL20: =99.068*3 -> 297.204 | DM20: =99.068*3 -> 297.204 | DN20: =147.793 -> 147.793 | DO20: =111.812*4 -> 447.248 | DP20: =536.689/8*7.5 -> 503.14594 | DS20: =SUM(BL20:DR20) -> 11630.421 | DU20: 241.737 | DV20: =50.62+97.613 -> 148.233 | DW20: 44.338 | DY20: =147.793*1.3 -> 192.1309 | DZ20: 53.401 | EB20: =65.52*10 -> 655.2 | EF20: 33.544 | EG20: =23.506/0.3*0.6 -> 47.012 | EH20: 29.72 | EI20: =147.793*0.8 -> 118.2344 | EJ20: =111.812*1.5 -> 167.718 | EK20: 111.812 | EL20: 111.812 | EN20: =536.689/8*5 -> 335.43062 | EO20: =147.793*5 -> 738.965 | EP20: =111.812*2 -> 223.624 | EQ20: 302.171 | ES20: =111.812*3 -> 335.436 | ET20: 20.126 | EU20: 61.369 | EV20: 73.896 | EX20: =402.523/4*5 -> 503.15375 | EY20: =192.131/1.3*2 -> 295.58615 | FB20: =52.602/0.6*1.2 -> 105.204 | FD20: 100.631 | FF20: =148.602/1.5*1.1 -> 108.9748 | FG20: 396.271 | FI20: =148.602/1.5*0.6 -> 59.4408 | FJ20: =65.52*10 -> 655.2 | FK20: =267.933 -> 267.933 | FL20: =147.793*0.7 -> 103.4551 | FM20: 147.793 | FN20: =50.4/0.5*0.6 -> 60.48 | FO20: =67.086*1.2 -> 80.5032 | FP20: =297.203 -> 297.203 | FQ20: =297.203 -> 297.203 | FR20: 118.235 | FS20: =100.8 -> 100.8 | FT20: =23.506/0.3*0.6 -> 47.012 | FU20: =SUM(DU20:FT20) -> 7790.9887 | GP20: =SUM(FW20:GO20) -> 0 | GQ20: =I20-GP20 -> 11396.4 | GR20: =I20 -> 11396.4 | GS20: =G20 -> 9027.017 | GT20: =E20 -> 11630.41 | GU20: =B20 -> сульфат магния б/водный, магний с/кисл.
A21: =A20+1 -> 12 | B21: сульфат магния Кизерит | C21: 0 | D21: 0 | E21: 0 | F21: 0 | G21: =ROUND(AVERAGE(D21:F21),3) -> 0 | H21: 0 | I21: 0 | BJ21: =SUM(K21:BI21) -> 0 | DS21: =SUM(BL21:DR21) -> 0 | FU21: =SUM(DU21:FT21) -> 0 | GP21: =SUM(FW21:GO21) -> 0 | GQ21: =I21-GP21 -> 0 | GR21: =I21 -> 0 | GS21: =G21 -> 0 | GT21: =E21 -> 0 | GU21: =B21 -> сульфат магния Кизерит
A22: =A21+1 -> 13 | B22: сера | C22: =69.23+71.59 -> 140.82 | D22: 81.34 | E22: 154.64 | F22: 44.27 | G22: =ROUND(AVERAGE(D22:F22),3) -> 93.417 | H22: 211.43 | I22: 167.16 | N22: 14.112 | P22: =3.384 -> 3.384 | Q22: 23.825 | AD22: 0.591 | AE22: 7.942 | AT22: 13.135 | AY22: 9.851 | BC22: =4.435 -> 4.435 | BE22: 3.055 | BF22: 1.018 | BJ22: =SUM(K22:BI22) -> 81.348 | CH22: =3.384*0.6 -> 2.0304 | CI22: 23.825 | CN22: 14.112 | CS22: 20.364 | CU22: 52.538 | CV22: 5.111 | CW22: 30.545 | DK22: 1.018 | DQ22: =3.394*1.5 -> 5.091 | DS22: =SUM(BL22:DR22) -> 154.6344 | EC22: 13.135 | EM22: 6.109 | ER22: =2.036*0.3 -> 0.6108 | FA22: 20.364 | FB22: =2.031/0.6*1.2 -> 4.062 | FU22: =SUM(DU22:FT22) -> 44.2808 | GP22: =SUM(FW22:GO22) -> 0 | GQ22: =I22-GP22 -> 167.16 | GR22: =I22 -> 167.16 | GS22: =G22 -> 93.417 | GT22: =E22 -> 154.64 | GU22: =B22 -> сера
A23: =A22+1 -> 14 | B23: сульфат железа | C23: 99.05 | D23: 10.75 | E23: =48.84+32.37 -> 81.21 | F23: =0.32+23.39 -> 23.71 | G23: =ROUND(AVERAGE(D23:F23),3) -> 38.557 | H23: =0.32+167.63 -> 167.95 | I23: 144.24 | AF23: 0.173 | AG23: 0.173 | AJ23: 7.479 | AR23: 0.087 | AS23: 0.13 | AZ23: 0.383 | BA23: 0.383 | BE23: =0.29+0.685 -> 0.975 | BF23: 0.975 | BJ23: =SUM(K23:BI23) -> 10.758 | CS23: 19.51 | CT23: 29.265 | CV23: 1.12 | CW23: 30.24 | CY23: 0.062 | DK23: 1.008 | DS23: =SUM(BL23:DR23) -> 81.205 | ED23: 0.13 | EE23: 0.087 | EM23: =1.912+0.1 -> 2.012 | ER23: =0.672*0.3 -> 0.2016 | EZ23: 1.12 | FA23: 20.16 | FU23: =SUM(DU23:FT23) -> 23.7106 | GP23: =SUM(FW23:GO23) -> 0 | GQ23: =I23-GP23 -> 144.24 | GR23: =I23 -> 144.24 | GS23: =G23 -> 38.557 | GT23: =E23 -> 81.21 | GU23: =B23 -> сульфат железа
A24: =A23+1 -> 15 | B24: медный купорос | C24: =71.702+127.488 -> 199.19 | D24: 218.5 | E24: 200.94 | F24: 223.58 | G24: =ROUND(AVERAGE(D24:F24),3) -> 214.34 | H24: 453.072 | I24: 229.492 | K24: =4.435*3 -> 13.305 | M24: =6.048*8 -> 48.384 | N24: =5.08 -> 5.08 | O24: 5.484 | W24: =6.653*1.5 -> 9.9795 | X24: =0.968*7 -> 6.776 | Z24: =0.968*2 -> 1.936 | AB24: =0.968*8 -> 7.744 | AC24: =6.048*6 -> 36.288 | AF24: 0.151 | AG24: 0.151 | AJ24: 6.492 | AK24: 1.21 | AM24: 1.129 | AO24: =1.411*2 -> 2.822 | AR24: 0.075 | AS24: 0.113 | AU24: 1.21 | AX24: =4.435*1.2 -> 5.322 | AZ24: 0.332 | BA24: 0.332 | BB24: 0.968 | BD24: =0.765/0.3 -> 2.55 | BF24: 0.202 | BG24: =60.48 -> 60.48 | BJ24: =SUM(K24:BI24) -> 218.5155 | BL24: 10.08 | BQ24: =4.435*3 -> 13.305 | BS24: =0.968*5.4 -> 5.2272 | BU24: =6.653*1.9 -> 12.6407 | BV24: 1.275 | BX24: =0.968*2.1 -> 2.0328 | CB24: =4.435*3 -> 13.305 | CC24: =5.322/1.2*3 -> 13.305 | CF24: =7.741/8*6 -> 5.80575 | CG24: 2.056 | CK24: =1.129/0.8*0.9 -> 1.270125 | CN24: 5.08 | CS24: 4.032 | CW24: 6.048 | CX24: =60.48 -> 60.48 | CZ24: =1.129/0.8*3 -> 4.23375 | DB24: =1.21*2 -> 2.42 | DF24: =1.21*0.6 -> 0.726 | DI24: =7.741/8 -> 0.967625 | DK24: 0.202 | DL24: =4.435*3 -> 13.305 | DM24: =4.435*3 -> 13.305 | DP24: =7.741/8*7.5 -> 7.2571875 | DQ24: =1.452*1.5 -> 2.178 | DR24: 0.363 | DS24: =SUM(BL24:DR24) -> 200.90014 | DV24: 9.979 | DW24: 0.765 | DX24: =1.129/0.8*0.9 -> 1.270125 | EA24: =0.677 -> 0.677 | EB24: =6.048*10 -> 60.48 | ED24: 0.113 | EE24: 0.075 | EF24: 0.968 | EH24: 1.331 | EK24: 1.21 | EL24: 1.21 | EN24: =7.741/8*5 -> 4.838125 | EW24: =1.21*2 -> 2.42 | FA24: 4.032 | FE24: =1.129/0.8*2.5 -> 3.528125 | FF24: =9.979/1.5*1.1 -> 7.3179333 | FG24: 17.741 | FI24: =9.979/1.5*0.6 -> 3.9916 | FJ24: =6.048*10 -> 60.48 | FK24: =13.306 -> 13.306 | FP24: =13.306 -> 13.306 | FQ24: =13.306 -> 13.306 | FS24: =1.21 -> 1.21 | FU24: =SUM(DU24:FT24) -> 223.55491 | GP24: =SUM(FW24:GO24) -> 0 | GQ24: =I24-GP24 -> 229.492 | GR24: =I24 -> 229.492 | GS24: =G24 -> 214.34 | GT24: =E24 -> 200.94 | GU24: =B24 -> медный купорос
A25: =A24+1 -> 16 | B25: цинковый купорос+ сульфат цинка | C25: =5.47+849.07 -> 854.54 | D25: 868.88 | E25: =216.61+531.79 -> 748.4 | F25: 893.57 | G25: =ROUND(AVERAGE(D25:F25),3) -> 836.95 | H25: 1468.21 | I25: 574.64 | K25: =18.568*3 -> 55.704 | M25: =24.802*8 -> 198.416 | N25: 18.568 | O25: 20.16 | P25: =2.631 -> 2.631 | W25: =27.853*1.5 -> 41.7795 | X25: =2.918*7 -> 20.426 | Z25: =2.918*2 -> 5.836 | AB25: =2.918*8 -> 23.344 | AC25: =24.802*6 -> 148.812 | AF25: 0.849 | AG25: 0.849 | AJ25: 36.606 | AK25: 2.785 | AM25: 2.653 | AO25: =3.316*2 -> 6.632 | AR25: 0.424 | AS25: 0.637 | AU25: 1.273 | AX25: =18.568*1.2 -> 22.2816 | AZ25: 1.872 | BA25: 1.872 | BB25: 2.918 | BD25: =0.859/0.3 -> 2.8633333 | BF25: 0.663 | BG25: =248.021 -> 248.021 | BJ25: =SUM(K25:BI25) -> 868.87543 | BL25: 9.947 | BQ25: =18.568*3 -> 55.704 | BS25: =2.918*5.4 -> 15.7572 | BU25: =27.853*1.9 -> 52.9207 | BV25: 1.432 | BX25: =2.918*2.1 -> 6.1278 | CB25: =18.568*3 -> 55.704 | CC25: =22.282/1.2*3 -> 55.705 | CF25: =23.343/8*6 -> 17.50725 | CG25: 7.56 | CH25: =2.631*0.6 -> 1.5786 | CK25: =2.653/0.8*0.9 -> 2.984625 | CN25: 18.568 | CS25: 13.263 | CW25: 19.895 | CX25: =248.021 -> 248.021 | CY25: 0.119 | CZ25: =2.653/0.8*3 -> 9.94875 | DB25: =2.785*2 -> 5.57 | DF25: =1.273*0.6 -> 0.7638 | DI25: =23.343/8 -> 2.917875 | DK25: 0.663 | DL25: =18.568*3 -> 55.704 | DM25: =18.568*3 -> 55.704 | DP25: =23.343/8*7.5 -> 21.884062 | DQ25: =7.958*1.5 -> 11.937 | DR25: 0.477 | DS25: =SUM(BL25:DR25) -> 748.36366 | DV25: 41.779 | DW25: 0.859 | DX25: =2.653/0.8*0.9 -> 2.984625 | EA25: =3.82 -> 3.82 | EB25: =24.802*10 -> 248.02 | ED25: 0.637 | EE25: 0.424 | EF25: 2.918 | EH25: 5.571 | EK25: 1.273 | EL25: 1.273 | EN25: =23.343/8*5 -> 14.589375 | EW25: =2.785*2 -> 5.57 | FA25: 13.263 | FB25: =1.579/0.6*1.2 -> 3.158 | FE25: =2.653/0.8*2.5 -> 8.290625 | FF25: =41.779/1.5*1.1 -> 30.637933 | FG25: 74.274 | FI25: =41.779/1.5*0.6 -> 16.7116 | FJ25: =24.802*10 -> 248.02 | FK25: =55.705 -> 55.705 | FN25: =0.928/0.5*0.6 -> 1.1136 | FP25: =55.705 -> 55.705 | FQ25: =55.705 -> 55.705 | FS25: =1.273 -> 1.273 | FU25: =SUM(DU25:FT25) -> 893.57476 | GP25: =SUM(FW25:GO25) -> 0 | GQ25: =I25-GP25 -> 574.64 | GR25: =I25 -> 574.64 | GS25: =G25 -> 836.95 | GT25: =E25 -> 748.4 | GU25: =B25 -> цинковый купорос+ сульфат цинка
A26: =A25+1 -> 17 | B26: сульфат марганца | C26: =479.34+154.75 -> 634.09 | D26: 508.28 | E26: =336.97+182.76 -> 519.73 | F26: =417.24+152.16 -> 569.4 | G26: =ROUND(AVERAGE(D26:F26),3) -> 532.47 | H26: 417.24 | I26: 1297.84 | K26: =11.813*3 -> 35.439 | M26: =14.648*8 -> 117.184 | N26: 16.427 | O26: 5.04 | W26: =17.719*1.5 -> 26.5785 | X26: =1.89*7 -> 13.23 | Z26: =1.89*2 -> 3.78 | AB26: =1.89*8 -> 15.12 | AC26: =14.648*6 -> 87.888 | AF26: 0.083 | AG26: 0.083 | AJ26: 3.623 | AK26: 2.599 | AM26: 3.15 | AO26: =3.938*2 -> 7.876 | AR26: 0.006 | AS26: 0.062 | AU26: 1.796 | AX26: =11.813*1.2 -> 14.1756 | AZ26: 0.183 | BA26: 0.195 | BB26: 1.89 | BD26: =1.243/0.3 -> 4.1433333 | BF26: 1.26 | BG26: =146.475 -> 146.475 | BJ26: =SUM(K26:BI26) -> 508.28643 | BL26: 7.875 | BQ26: =11.813*3 -> 35.439 | BS26: =1.89*5.4 -> 10.206 | BU26: =17.719*1.9 -> 33.6661 | BV26: 2.071 | BX26: =1.89*2.1 -> 3.969 | CB26: =11.813*3 -> 35.439 | CC26: =14.175/1.2*3 -> 35.4375 | CF26: =15.12/8*6 -> 11.34 | CG26: 1.89 | CK26: =3.15/0.8*0.9 -> 3.54375 | CN26: 16.427 | CS26: 25.2 | CW26: 37.8 | CX26: =146.475 -> 146.475 | CY26: 0.054 | CZ26: =3.15/0.8*3 -> 11.8125 | DB26: =2.599*2 -> 5.198 | DF26: =1.796*0.6 -> 1.0776 | DI26: =15.12/8 -> 1.89 | DK26: 1.26 | DL26: =11.813*3 -> 35.439 | DM26: =11.813*3 -> 35.439 | DP26: =15.12/8*7.5 -> 14.175 | DQ26: =4.199*1.5 -> 6.2985 | DR26: 0.283 | DS26: =SUM(BL26:DR26) -> 519.70495 | DV26: 26.578 | DW26: 1.243 | DX26: =3.15/0.8*0.9 -> 3.54375 | EA26: =0.374 -> 0.374 | EB26: =14.648*10 -> 146.48 | ED26: 0.009 | EE26: 0.042 | EF26: 1.89 | EH26: 3.544 | EK26: 1.796 | EL26: 1.796 | EN26: =15.12/8*5 -> 9.45 | EW26: =2.599*2 -> 5.198 | FA26: 25.2 | FE26: =3.15/0.8*2.5 -> 9.84375 | FF26: =26.578/1.5*1.1 -> 19.490533 | FG26: 47.25 | FI26: =26.578/1.5*0.6 -> 10.6312 | FJ26: =14.648*10 -> 146.48 | FK26: =35.438 -> 35.438 | FN26: =0.394/0.5*0.6 -> 0.4728 | FP26: =35.438 -> 35.438 | FQ26: =35.438 -> 35.438 | FS26: =1.796 -> 1.796 | FU26: =SUM(DU26:FT26) -> 569.42203 | GP26: =SUM(FW26:GO26) -> 0 | GQ26: =I26-GP26 -> 1297.84 | GR26: =I26 -> 1297.84 | GS26: =G26 -> 532.47 | GT26: =E26 -> 519.73 | GU26: =B26 -> сульфат марганца
A27: =A26+1 -> 18 | B27: калий йод | C27: =17.59 -> 17.59 | D27: 13.002 | E27: =7.878+11.047 -> 18.925 | F27: 13.96 | G27: =ROUND(AVERAGE(D27:F27),3) -> 15.296 | H27: 38.953 | I27: 24.993 | K27: =0.219*3 -> 0.657 | L27: 0.657 | M27: =0.175*8 -> 1.4 | N27: 0.174 | O27: 0.164 | P27: =0.053 -> 0.053 | Q27: 0.077 | R27: =0.053*3 -> 0.159 | T27: =0.139 -> 0.139 | U27: =0.044*1.5 -> 0.066 | V27: =0.053*4 -> 0.212 | W27: =0.219*1.5 -> 0.3285 | X27: =0.044*7 -> 0.308 | Z27: =0.044*2 -> 0.088 | AA27: =0.053*4 -> 0.212 | AB27: =0.044*8 -> 0.352 | AC27: =0.175*6 -> 1.05 | AE27: 0.21 | AF27: 0.019 | AG27: 0.019 | AH27: 0.131 | AI27: =0.219*4 -> 0.876 | AJ27: 0.84 | AK27: 0.078 | AL27: 0.026 | AM27: 0.112 | AN27: 0.153 | AO27: =0.14*2 -> 0.28 | AP27: =0.139*1.3 -> 0.1807 | AQ27: 0.047 | AR27: 0.01 | AS27: 0.015 | AT27: 0.351 | AU27: 0.053 | AV27: =0.139 -> 0.139 | AW27: 0.657 | AX27: =0.219*1.2 -> 0.2628 | AY27: 0.263 | AZ27: 0.043 | BA27: 0.043 | BB27: 0.044 | BD27: =0.042/0.3 -> 0.14 | BE27: 0.044 | BF27: 0.002 | BG27: =1.753 -> 1.753 | BH27: =0.139*0.6 -> 0.0834 | BI27: =0.053*1.1 -> 0.0583 | BJ27: =SUM(K27:BI27) -> 13.0297 | BL27: 0.877 | BN27: =0.139*1.5 -> 0.2085 | BO27: =0.219*2.4 -> 0.5256 | BP27: =0.139 -> 0.139 | BQ27: =0.219*3 -> 0.657 | BS27: =0.044*5.4 -> 0.2376 | BT27: 0.657 | BU27: =0.219*1.9 -> 0.4161 | BV27: 0.069 | BW27: 0.105 | BX27: =0.044*2.1 -> 0.0924 | BY27: =0.044*2 -> 0.088 | BZ27: =0.139 -> 0.139 | CA27: =0.053*4 -> 0.212 | CB27: =0.219*3 -> 0.657 | CC27: =0.263/1.2*3 -> 0.6575 | CD27: =0.053*4 -> 0.212 | CE27: 0.139 | CF27: =0.351/8*6 -> 0.26325 | CG27: 0.061 | CH27: =0.053*0.6 -> 0.0318 | CI27: 0.077 | CK27: =0.112/0.8*0.9 -> 0.126 | CL27: =0.032/0.6*0.9 -> 0.048 | CM27: 0.026 | CN27: 0.174 | CO27: =0.044*2 -> 0.088 | CP27: =0.139*0.3 -> 0.0417 | CQ27: 0.657 | CR27: 0.139 | CS27: 0.035 | CT27: 3.287 | CU27: 1.402 | CV27: 0.122 | CW27: 0.053 | CX27: =1.753 -> 1.753 | CY27: 0.003 | CZ27: =0.112/0.8*3 -> 0.42 | DA27: =0.18/1.3*1.5 -> 0.20769231 | DB27: =0.076*2 -> 0.152 | DC27: =0.877/4*4.5 -> 0.986625 | DD27: 0.131 | DE27: 0.153 | DF27: =0.053*0.6 -> 0.0318 | DG27: =0.139 -> 0.139 | DH27: =0.053 -> 0.053 | DI27: =0.351/8 -> 0.043875 | DK27: 0.002 | DL27: =0.219*3 -> 0.657 | DM27: =0.219*3 -> 0.657 | DN27: =0.139 -> 0.139 | DO27: =0.053*4 -> 0.212 | DP27: =0.351/8*7.5 -> 0.3290625 | DQ27: =0.073*1.5 -> 0.1095 | DR27: 0.016 | DS27: =SUM(BL27:DR27) -> 18.916005 | DU27: 0.526 | DV27: 0.329 | DW27: 0.042 | DX27: =0.112/0.8*0.9 -> 0.126 | DY27: =0.139*1.3 -> 0.1807 | EA27: =0.088 -> 0.088 | EB27: =0.175*10 -> 1.75 | EC27: 0.351 | ED27: 0.015 | EE27: 0.01 | EF27: 0.044 | EG27: =0.105/0.3*0.6 -> 0.21 | EH27: 0.066 | EI27: =0.139*0.8 -> 0.1112 | EJ27: =0.053*1.5 -> 0.0795 | EK27: 0.053 | EL27: 0.053 | EM27: 0.088 | EN27: =0.351/8*5 -> 0.219375 | EO27: =0.139*5 -> 0.695 | EP27: =0.053*2 -> 0.106 | EQ27: 0.657 | ER27: =0.029*0.3 -> 0.0087 | ES27: =0.053*3 -> 0.159 | ET27: 0.026 | EU27: 0.047 | EV27: 0.077 | EW27: =0.076*2 -> 0.152 | EX27: =0.877/4*5 -> 1.09625 | EY27: =0.18/1.3*2 -> 0.27692308 | EZ27: 0.122 | FA27: 0.035 | FB27: =0.032/0.6*1.2 -> 0.064 | FD27: 0.131 | FE27: =0.112/0.8*2.5 -> 0.35 | FF27: =0.329/1.5*1.1 -> 0.24126667 | FG27: 0.877 | FI27: =0.329/1.5*0.6 -> 0.1316 | FJ27: =0.175*10 -> 1.75 | FK27: =0.657 -> 0.657 | FL27: =0.139*0.7 -> 0.0973 | FM27: 0.139 | FO27: =0.044*1.2 -> 0.0528 | FP27: =0.657 -> 0.657 | FQ27: =0.657 -> 0.657 | FR27: 0.111 | FS27: =0.053 -> 0.053 | FT27: =0.105/0.3*0.6 -> 0.21 | FU27: =SUM(DU27:FT27) -> 13.978615 | GP27: =SUM(FW27:GO27) -> 0 | GQ27: =I27-GP27 -> 24.993 | GR27: =I27 -> 24.993 | GS27: =G27 -> 15.296 | GT27: =E27 -> 18.925 | GU27: =B27 -> калий йод
A28: =A27+1 -> 19 | B28: йодат кальция | C28: 0 | D28: 0 | E28: 0 | F28: 0 | G28: =ROUND(AVERAGE(D28:F28),3) -> 0 | H28: 0 | I28: 0 | BJ28: =SUM(K28:BI28) -> 0 | DS28: =SUM(BL28:DR28) -> 0 | FU28: =SUM(DU28:FT28) -> 0 | GP28: =SUM(FW28:GO28) -> 0 | GQ28: =I28-GP28 -> 0 | GR28: =I28 -> 0 | GS28: =G28 -> 0 | GT28: =E28 -> 0 | GU28: =B28 -> йодат кальция
A29: =A28+1 -> 20 | B29: кобальт у/к | C29: =2.445+10.61 -> 13.055 | D29: 7.9 | E29: 13.57 | F29: 8.36 | G29: =ROUND(AVERAGE(D29:F29),3) -> 9.943 | H29: 17.92 | I29: 9.56 | K29: =0.129*3 -> 0.387 | L29: 0.386 | M29: =0.097*8 -> 0.776 | N29: 0.15 | O29: 0.06 | P29: =0.03 -> 0.03 | Q29: 0.013 | R29: =0.03*3 -> 0.09 | T29: =0.075 -> 0.075 | U29: =0.026*1.5 -> 0.039 | V29: =0.03*4 -> 0.12 | W29: =0.129*1.5 -> 0.1935 | X29: =0.026*7 -> 0.182 | Z29: =0.026*2 -> 0.052 | AA29: =0.03*4 -> 0.12 | AB29: =0.026*8 -> 0.208 | AC29: =0.097*6 -> 0.582 | AE29: 0.103 | AF29: 0.023 | AG29: 0.023 | AH29: 0.077 | AI29: =0.129*4 -> 0.516 | AJ29: 0.987 | AK29: 0.047 | AL29: 0.015 | AM29: 0.051 | AN29: 0.075 | AO29: =0.064*2 -> 0.128 | AP29: =0.075*1.3 -> 0.0975 | AQ29: 0.027 | AR29: 0.011 | AS29: 0.017 | AT29: 0.172 | AU29: 0.03 | AV29: =0.075 -> 0.075 | AW29: 0.386 | AX29: =0.129*1.2 -> 0.1548 | AY29: 0.129 | AZ29: 0.05 | BA29: 0.05 | BB29: 0.026 | BD29: =0.023/0.3 -> 0.076666667 | BE29: 0.048 | BF29: 0.019 | BG29: =0.965 -> 0.965 | BH29: =0.075*0.6 -> 0.045 | BI29: =0.03*1.1 -> 0.033 | BJ29: =SUM(K29:BI29) -> 7.9204667 | BL29: 0.429 | BN29: =0.075*1.5 -> 0.1125 | BO29: =0.129*2.4 -> 0.3096 | BP29: =0.075 -> 0.075 | BQ29: =0.129*3 -> 0.387 | BS29: =0.026*5.4 -> 0.1404 | BT29: 0.386 | BU29: =0.129*1.9 -> 0.2451 | BV29: 0.038 | BW29: 0.026 | BX29: =0.026*2.1 -> 0.0546 | BY29: =0.026*2 -> 0.052 | BZ29: =0.075 -> 0.075 | CA29: =0.03*4 -> 0.12 | CB29: =0.129*3 -> 0.387 | CC29: =0.154/1.2*3 -> 0.385 | CD29: =0.03*4 -> 0.12 | CE29: 0.075 | CF29: =0.206/8*6 -> 0.1545 | CG29: 0.023 | CH29: =0.03*0.6 -> 0.018 | CI29: 0.013 | CK29: =0.051/0.8*0.9 -> 0.057375 | CL29: =0.018/0.6*0.9 -> 0.027 | CM29: 0.015 | CN29: 0.15 | CO29: =0.026*2 -> 0.052 | CP29: =0.075*0.3 -> 0.0225 | CQ29: 0.386 | CR29: 0.075 | CS29: 0.386 | CT29: 3.86 | CU29: 0.687 | CV29: 0.143 | CW29: 0.579 | CX29: =0.965 -> 0.965 | CZ29: =0.051/0.8*3 -> 0.19125 | DA29: =0.098/1.3*1.5 -> 0.11307692 | DB29: =0.047*2 -> 0.094 | DC29: =0.515/4*4.5 -> 0.579375 | DD29: 0.077 | DE29: 0.075 | DF29: =0.03*0.6 -> 0.018 | DG29: =0.075 -> 0.075 | DH29: =0.03 -> 0.03 | DI29: =0.206/8 -> 0.02575 | DK29: 0.019 | DL29: =0.129*3 -> 0.387 | DM29: =0.129*3 -> 0.387 | DN29: =0.075 -> 0.075 | DO29: =0.03*4 -> 0.12 | DP29: =0.206/8*7.5 -> 0.193125 | DQ29: =0.032*1.5 -> 0.048 | DR29: 0.008 | DS29: =SUM(BL29:DR29) -> 13.546152 | DU29: 0.309 | DV29: 0.193 | DW29: 0.023 | DX29: =0.051/0.8*0.9 -> 0.057375 | DY29: =0.075*1.3 -> 0.0975 | EA29: =0.103 -> 0.103 | EB29: =0.097*10 -> 0.97 | EC29: 0.172 | ED29: 0.017 | EE29: 0.011 | EF29: 0.026 | EG29: =0.026/0.3*0.6 -> 0.052 | EH29: 0.039 | EI29: =0.075*0.8 -> 0.06 | EJ29: =0.03*1.5 -> 0.045 | EK29: 0.03 | EL29: 0.03 | EM29: 0.097 | EN29: =0.206/8*5 -> 0.12875 | EO29: =0.075*5 -> 0.375 | EP29: =0.03*2 -> 0.06 | EQ29: 0.386 | ER29: =0.032*0.3 -> 0.0096 | ES29: =0.03*3 -> 0.09 | ET29: 0.015 | EU29: 0.027 | EV29: 0.038 | EW29: =0.047*2 -> 0.094 | EX29: =0.515/4*5 -> 0.64375 | EY29: =0.098/1.3*2 -> 0.15076923 | EZ29: 0.143 | FA29: 0.386 | FB29: =0.018/0.6*1.2 -> 0.036 | FD29: 0.077 | FE29: =0.051/0.8*2.5 -> 0.159375 | FF29: =0.193/1.5*1.1 -> 0.14153333 | FG29: 0.515 | FI29: =0.193/1.5*0.6 -> 0.0772 | FJ29: =0.097*10 -> 0.97 | FK29: =0.386 -> 0.386 | FL29: =0.075*0.7 -> 0.0525 | FM29: 0.075 | FN29: =0.005/0.5*0.6 -> 0.006 | FO29: =0.026*1.2 -> 0.0312 | FP29: =0.386 -> 0.386 | FQ29: =0.386 -> 0.386 | FR29: 0.06 | FS29: =0.03 -> 0.03 | FT29: =0.026/0.3*0.6 -> 0.052 | FU29: =SUM(DU29:FT29) -> 8.3195526 | GP29: =SUM(FW29:GO29) -> 0 | GQ29: =I29-GP29 -> 9.56 | GR29: =I29 -> 9.56 | GS29: =G29 -> 9.943 | GT29: =E29 -> 13.57 | GU29: =B29 -> кобальт у/к
A30: =A29+1 -> 21 | B30: селенит натрия | C30: 2.309 | D30: 1.864 | E30: 2.596 | F30: =2.411+0.113 -> 2.524 | G30: =ROUND(AVERAGE(D30:F30),3) -> 2.328 | H30: 2.411 | I30: 19.887 | K30: =0.078*3 -> 0.234 | M30: =0.045*8 -> 0.36 | N30: 0.094 | O30: 0.045 | W30: =0.118*1.5 -> 0.177 | Y30: =0.004*3 -> 0.012 | AC30: =0.045*6 -> 0.27 | AF30: 0.004 | AG30: 0.004 | AJ30: 0.021 | AK30: 0.016 | AM30: 0.013 | AO30: =0.016*2 -> 0.032 | AR30: 0.002 | AS30: 0.003 | AX30: =0.078*1.2 -> 0.0936 | AZ30: 0.008 | BA30: 0.008 | BD30: =0.007/0.3 -> 0.023333333 | BF30: 0.004 | BG30: =0.448 -> 0.448 | BJ30: =SUM(K30:BI30) -> 1.8719333 | BL30: 0.095 | BQ30: =0.078*3 -> 0.234 | BU30: =0.118*1.9 -> 0.2242 | BV30: 0.012 | CB30: =0.078*3 -> 0.234 | CC30: =0.094/1.2*3 -> 0.235 | CG30: 0.017 | CJ30: 0.013 | CK30: =0.013/0.8*0.9 -> 0.014625 | CN30: 0.094 | CS30: 0.076 | CT30: 0.081 | CV30: 0.053 | CW30: 0.114 | CX30: =0.448 -> 0.448 | CZ30: =0.013/0.8*3 -> 0.04875 | DB30: =0.016*2 -> 0.032 | DK30: 0.004 | DL30: =0.078*3 -> 0.234 | DM30: =0.078*3 -> 0.234 | DQ30: =0.056*1.5 -> 0.084 | DR30: 0.002 | DS30: =SUM(BL30:DR30) -> 2.583575 | DV30: 0.176 | DW30: 0.007 | DX30: =0.013/0.8*0.9 -> 0.014625 | EB30: =0.045*10 -> 0.45 | ED30: 0.003 | EE30: 0.002 | EH30: 0.024 | EW30: =0.016*2 -> 0.032 | EZ30: 0.022 | FA30: 0.076 | FE30: =0.013/0.8*2.5 -> 0.040625 | FF30: =0.176/1.5*1.1 -> 0.12906667 | FG30: 0.314 | FI30: =0.176/1.5*0.6 -> 0.0704 | FJ30: =0.045*10 -> 0.45 | FK30: =0.235 -> 0.235 | FN30: =0.017/0.5*0.6 -> 0.0204 | FP30: =0.235 -> 0.235 | FQ30: =0.235 -> 0.235 | FU30: =SUM(DU30:FT30) -> 2.5361167 | GP30: =SUM(FW30:GO30) -> 0 | GQ30: =I30-GP30 -> 19.887 | GR30: =I30 -> 19.887 | GS30: =G30 -> 2.328 | GT30: =E30 -> 2.596 | GU30: =B30 -> селенит натрия
A31: =A30+1 -> 22 | B31: Метионин | C31: 1921.02 | D31: 0 | E31: 0 | F31: 0 | G31: =ROUND(AVERAGE(D31:F31),3) -> 0 | H31: 0 | I31: 0 | BJ31: =SUM(K31:BI31) -> 0 | DS31: =SUM(BL31:DR31) -> 0 | FU31: =SUM(DU31:FT31) -> 0 | GP31: =SUM(FW31:GO31) -> 0 | GQ31: =I31-GP31 -> 0 | GR31: =I31 -> 0 | GS31: =G31 -> 0 | GT31: =E31 -> 0 | GU31: =B31 -> Метионин
A32: =A31+1 -> 23 | B32: МиТаргет (Метионин защищённый) | C32: =60.23+110.33 -> 170.56 | D32: 232.64 | E32: 221.93 | F32: 212.94 | G32: =ROUND(AVERAGE(D32:F32),3) -> 222.503 | H32: 335.1 | I32: =122.16+50 -> 172.16 | P32: =26.784 -> 26.784 | Q32: 25.056 | AH32: 120.528 | AL32: 24.106 | AQ32: 36.158 | BJ32: =SUM(K32:BI32) -> 232.632 | CH32: =26.784*0.6 -> 16.0704 | CI32: =25.056 -> 25.056 | CL32: =24.106/0.6*0.9 -> 36.159 | CM32: 24.106 | DD32: 120.528 | DS32: =SUM(BL32:DR32) -> 221.9194 | ET32: 24.106 | EU32: 36.158 | FB32: =16.07/0.6*1.2 -> 32.14 | FD32: 120.528 | FU32: =SUM(DU32:FT32) -> 212.932 | GP32: =SUM(FW32:GO32) -> 0 | GQ32: =I32-GP32 -> 172.16 | GR32: =I32 -> 172.16 | GS32: =G32 -> 222.503 | GT32: =E32 -> 221.93 | GU32: =B32 -> МиТаргет (Метионин защищённый)
A33: =A32+1 -> 24 | B33: монокальцийфосфат (МКФ) | C33: =5640.84 -> 5640.84 | D33: =64.21+3408.67 -> 3472.88 | E33: 6408.59 | F33: 6041.92 | G33: =ROUND(AVERAGE(D33:F33),3) -> 5307.797 | H33: 7182.74 | I33: =1140.82+20000 -> 21140.82 | K33: =158.76*3 -> 476.28 | L33: 468.72 | O33: 101.645 | T33: =34.272 -> 34.272 | W33: =156.331*1.5 -> 234.4965 | AH33: 51.408 | AI33: =159.264*4 -> 637.056 | AK33: 110.376 | AL33: 10.282 | AM33: 105.719 | AN33: 33.264 | AO33: =132.149*2 -> 264.298 | AP33: =34.272*1.3 -> 44.5536 | AV33: =34.272 -> 34.272 | AW33: 468.72 | AX33: =159.566*1.2 -> 191.4792 | BD33: =10.282/0.3 -> 34.273333 | BE33: 151.2 | BH33: =34.272*0.6 -> 20.5632 | BJ33: =SUM(K33:BI33) -> 3472.8778 | BL33: 428.4 | BN33: =34.272*1.5 -> 51.408 | BO33: =151.2*2.4 -> 362.88 | BP33: 34.272 | BQ33: =158.962*3 -> 476.886 | BT33: 468.72 | BU33: =156.744*1.9 -> 297.8136 | BV33: 17.136 | BW33: 79.834 | BZ33: =34.272 -> 34.272 | CB33: =158.962*3 -> 476.886 | CC33: =191.117/1.2*3 -> 477.7925 | CE33: 34.272 | CG33: 38.117 | CK33: =105.719/0.8*0.9 -> 118.93387 | CM33: 10.282 | CP33: =34.272*0.3 -> 10.2816 | CQ33: 464.184 | CR33: 34.272 | CZ33: =105.719/0.8*3 -> 396.44625 | DA33: =44.554/1.3*1.5 -> 51.408462 | DB33: =110.376*2 -> 220.752 | DC33: =637.056/4*4.5 -> 716.688 | DD33: 51.408 | DE33: 33.264 | DG33: =34.272 -> 34.272 | DL33: =159.264*3 -> 477.792 | DM33: =158.558*3 -> 475.674 | DN33: =34.272 -> 34.272 | DS33: =SUM(BL33:DR33) -> 6408.6193 | DU33: 362.154 | DV33: 235.116 | DW33: 10.282 | DX33: =105.719/0.8*0.9 -> 118.93387 | DY33: =34.272*1.3 -> 44.5536 | EG33: =79.834/0.3*0.6 -> 159.668 | EH33: 47.568 | EI33: =34.272*0.8 -> 27.4176 | EM33: 302.4 | EO33: =34.272*5 -> 171.36 | EQ33: 464.184 | ER33: =100.8*0.3 -> 30.24 | ET33: 10.282 | EV33: 16.632 | EW33: =110.376*2 -> 220.752 | EX33: =637.056/4*5 -> 796.32 | EY33: =44.554/1.3*2 -> 68.544615 | FD33: 51.408 | FE33: =105.719/0.8*2.5 -> 330.37187 | FF33: =234.814/1.5*1.1 -> 172.19693 | FG33: 631.008 | FI33: =234.814/1.5*0.6 -> 93.9256 | FK33: =475.675 -> 475.675 | FL33: =34.272*0.7 -> 23.9904 | FM33: 34.272 | FP33: =477.792 -> 477.792 | FQ33: =477.792 -> 477.792 | FR33: 27.418 | FT33: =79.834/0.3*0.6 -> 159.668 | FU33: =SUM(DU33:FT33) -> 6041.9255 | GP33: =SUM(FW33:GO33) -> 0 | GQ33: =I33-GP33 -> 21140.82 | GR33: =I33 -> 21140.82 | GS33: =G33 -> 5307.797 | GT33: =E33 -> 6408.59 | GU33: =B33 -> монокальцийфосфат (МКФ)
